Workbook

Sheet README
A1: TARU Economics Model (D8), v0.1
A2: Status | B2: 30 Sep 2026. Tabs: README, Scenarios (switch + results), Inputs + Sizing (market), Assumptions, Range_Cost, Channel_Waterfalls, Demand_Cash_24M.
A3: Colour code | B3: Blue text = input (change these). Green text = link to the Inputs tab. Black = formula. Yellow fill = placeholder awaiting your own data (survey, price audit).
A4: Rule | B4: Every input carries a register ID (R###) from the sources register. No number is typed into a formula.
A5: Sizing logic | B5: Top-down: men's ethnic wear × ₹/US$ × organised share × premium share × four-metro share. Bottom-up: H × m × f × ASP, where H = target households (income > ₹30 lakh) in the four metros, m = men aged 40–60 per household, f = sets bought per man per year, ASP = average selling price. Gifted purchases for fathers are inside f (they are sets the father receives).
A6: Disclaimer | B6: TARU is a fictional brand created for an independent student portfolio project. Market, competitor and regulatory facts come from public sources as cited. Consumer findings come from the author's own research with a convenience sample. Costs, targets and financial projections are illustrative assumptions.

Sheet Scenarios
A1: Scenario switch and results
A2: Pick a scenario in C5. Every sheet recalculates.
B4: Driver | C4: Selected | D4: Downside | E4: Base | F4: Upside
B5: Scenario (1 = Downside, 2 = Base, 3 = Upside) | C5: 2
B6: Volume multiplier | C6: =CHOOSE($C$5,D6,E6,F6) -> 1 | D6: 0.6 | E6: 1 | F6: 1.4
B7: Price realisation (share of list price achieved) | C7: =CHOOSE($C$5,D7,E7,F7) -> 1 | D7: 0.95 | E7: 1 | F7: 1
B8: Acquisition cost multiplier | C8: =CHOOSE($C$5,D8,E8,F8) -> 1 | D8: 1.4 | E8: 1 | F8: 0.8
B9: Fixed overhead multiplier | C9: =CHOOSE($C$5,D9,E9,F9) -> 1 | D9: 1.1 | E9: 1 | F9: 1
B12: RESULTS (selected scenario)
B13: 24-month revenue ex-GST (₹) | C13: =SUM(Demand_Cash_24M!B9:Y9) -> 18343454
B14: 24-month contribution (₹) | C14: =SUM(Demand_Cash_24M!B12:Y12) -> 1704972
B15: 24-month EBITDA (₹) | C15: =SUM(Demand_Cash_24M!B16:Y16) -> -7255028
B16: Year-2 EBITDA (₹) | C16: =SUM(Demand_Cash_24M!N16:Y16) -> -3014392.5
B17: Peak funding need: lowest cumulative cash (₹) | C17: =MIN(Demand_Cash_24M!B21:Y21) -> -7758839.3
B18: Month of lowest cash | C18: =INDEX(Demand_Cash_24M!B4:Y4,MATCH(MIN(Demand_Cash_24M!B21:Y21),Demand_Cash_24M!B21:Y21,0)) -> 47270
B19: First month with positive EBITDA | C19: =IFERROR(INDEX(Demand_Cash_24M!B4:Y4,MATCH(TRUE(),INDEX(Demand_Cash_24M!B16:Y16>0,0),0)),"none in 24 months") -> none in 24 months
B20: Blended contribution per set (₹) | C20: =Channel_Waterfalls!B25*Scenarios!C7 -> 355.20251
B21: Break-even sets per month (fixed + content ÷ contribution per set) | C21: =IF(Channel_Waterfalls!B25<=0,"never",(Assumptions!$C$36*C9+Assumptions!$C$37)/Channel_Waterfalls!B25) -> 957.20045
B22: Average sets per month, year 2 | C22: =Assumptions!$C$40*C6/12 -> 250

Sheet Inputs
A1: Input | B1: Value | C1: Unit | D1: Register ID | E1: Note
A2: Men's ethnic wear market | B2: 3.1 | C2: US$ bn | D2: R009 | E2: Derived estimate
A3: INR per US$ | B3: 86 | C3: ₹ per US$ | D3: R086 | E3: Assumption; update
A4: Organised share of ethnic wear (midpoint of 15–20%) | B4: 0.175 | C4: % | D4: R004
A5: Premium share of organised ethnic wear | B5: 0.3 | C5: % | D5: R006
A6: Four-metro share of premium spend | B6: 0.3 | C6: % | D6: R094 | E6: Assumption
A7: Greater Mumbai UA population, 2011 | B7: 18394912 | C7: persons | D7: R084
A8: Delhi UA population, 2011 | B8: 16349831 | C8: persons | D8: R084
A9: Bangalore UA population, 2011 | B9: 8520435 | C9: persons | D9: R084
A10: Pune UA population, 2011 | B10: 5057709 | C10: persons | D10: R084
A11: Urban population growth factor 2011→2026 | B11: 1.35 | C11: × | D11: R087 | E11: Assumption
A12: Delhi UA → Delhi NCR uplift | B12: 1.35 | C12: × | D12: R089 | E12: Assumption
A13: Average household size | B13: 4.2 | C13: persons | D13: R088 | E13: Assumption
A14: Share of households with income > ₹30 lakh | B14: 0.12 | C14: % | D14: R090 | E14: Assumption; biggest uncertainty
A15: Men aged 40–60 per target household | B15: 0.4 | C15: men | D15: R091 | E15: Assumption
A16: Sets bought per man per year | B16: 1.5 | C16: sets/yr | D16: R092 | E16: Placeholder until survey
A17: Average selling price per premium set | B17: 5000 | C17: ₹ | D17: R093 | E17: Placeholder until price audit
A18: Share of SAM reachable in 24 months | B18: 0.005 | C18: % | D18: R095 | E18: Placeholder until D8 channel plan

Sheet Assumptions
A1: Assumptions for range, cost, channel and cash
A2: Blue = input. Every row cites a source or says 'Assumption'. Yellow = low confidence; test in Scenarios.
A4: Key | B4: Input | C4: Everyday | D4: Festive | E4: Ceremonial | F4: Unit | G4: Source / note
A5: price | B5: Retail price per set (MRP = selling; no markdowns) | C5: 2499 | D5: 4999 | E5: 8999 | F5: ₹ | G5: Price audit + VW: everyday held under ₹2,500 GST slab; festive ~10% over Manyavar festive median (₹4,499); ceremonial inside survey acceptable range (₹4,800–11,250)
A6: fab_m | B6: Fabric per set | C6: 5 | D6: 5 | E6: 7.5 | F6: metres | G6: Assumption: kurta ~2.75 m + pyjama ~2.25 m; ceremonial adds Nehru jacket
A7: fab_rate | B7: Certified-organic fabric cost | C7: 180 | D7: 350 | E7: 450 | F7: ₹/m | G7: IndiaMART GOTS organic cotton listings ₹110–350/m (30 Sep 2026); festive/ceremonial = linen or handloom premium (assumption)
A8: cmt | B8: Cut-make-trim (stitching) per set | C8: 350 | D8: 500 | E8: 1200 | F8: ₹ | G8: IndiaMART kurta-pajama job work ₹300–700/set; ceremonial with jacket (assumption)
A9: trims | B9: Buttons, thread, labels, swing tag | C9: 60 | D9: 120 | E9: 250 | F9: ₹ | G9: Assumption
A10: pack | B10: Packaging (bag / box, tissue, proof card) | C10: 90 | D10: 150 | E10: 300 | F10: ₹ | G10: Assumption; ceremonial = rigid box (brand book 5.1)
A11: cert | B11: Certification and traceability per set | C11: 30 | D11: 30 | E11: 40 | F11: ₹ | G11: Assumption: GOTS licence + QR trail spread over volume
A12: waste | B12: Fabric wastage and QC rejects | C12: 0.08 | D12: 0.08 | E12: 0.1 | F12: % of materials | G12: Assumption
A13: line_mix | B13: Share of units | C13: 0.45 | D13: 0.4 | E13: 0.15 | F13: % | G13: Assumption; Trends: festive/wedding searches dominate Oct–Nov
A15: GST
A16: gst_low | B16: GST at or below ₹2,500 per piece | C16: 0.05 | G16: Register R048 (w.e.f. 22 Sep 2025)
A17: gst_high | B17: GST above ₹2,500 per piece | C17: 0.18 | G17: Register R048
A18: gst_cut | B18: GST threshold | C18: 2500 | G18: Register R048. Applied per set here; per-piece billing of a set could lower tax (note for D8)
A20: CHANNELS
A21: Key | B21: Input | C21: D2C website | D21: Marketplace | E21: Pop-up | F21: Corporate gifting | G21: Source / note
A22: mix | B22: Share of units | C22: 0.35 | D22: 0.3 | E22: 0.2 | F22: 0.15 | G22: Assumption; survey G1 ranks marketplace and brand website first (direction only)
A23: disc | B23: Price discount to customer / buyer | C23: 0 | D23: 0 | E23: 0 | F23: 0.15 | G23: Assumption: gifting bulk rate 15%
A24: comm | B24: Commission (% of selling price) | C24: 0 | D24: 0.275 | E24: 0 | F24: 0 | G24: Register R069: Myntra 25–30% (press estimate, L)
A25: fixed_fee | B25: Fixed fee per order | C25: 0 | D25: 25 | E25: 0 | F25: 0 | G25: Register R070: ₹15–35 (L)
A26: pg | B26: Payment gateway (% incl. 18% GST on fee) | C26: 0.0236 | D26: 0 | E26: 0.0236 | F26: 0 | G26: Register R076: Razorpay 2% + GST
A27: ship | B27: Forward shipping per order | C27: 60 | D27: 90 | E27: 0 | F27: 30 | G27: Register R073/R071: ₹25–45/500 g aggregator; ₹55–120 Myntra; gifting = bulk
A28: ret | B28: Return rate | C28: 0.2 | D28: 0.25 | E28: 0.03 | F28: 0.02 | G28: Register R062/R063: fashion 25–40%; own site with fit guide lower (assumption)
A29: rev_ship | B29: Reverse shipping per return | C29: 70 | D29: 90 | E29: 0 | F29: 0 | G29: Register R071: reverse ≈ forward
A30: loss | B30: Unsellable share of returned value | C30: 0.1 | D30: 0.1 | E30: 0.1 | F30: 0.1 | G30: Assumption
A31: cod | B31: COD share of orders | C31: 0.64 | D31: 0 | E31: 0 | F31: 0 | G31: Survey G4 (64%, direction only)
A32: rto | B32: Return-to-origin rate on COD orders | C32: 0.2 | D32: 0 | E32: 0 | F32: 0 | G32: Register R064: RTO peaks ~39%; 20% assumed on an average month
A33: acq | B33: Acquisition or venue cost per unit | C33: 550 | D33: 150 | E33: 450 | F33: 200 | G33: Assumption: D2C paid social CAC; marketplace ads; pop-up stall ~₹40k per 3-day event ÷ ~90 sets; gifting sales effort
A35: OVERHEADS AND VOLUME
A36: fixed_m | B36: Fixed overheads per month (2 staff + founder draw, studio, software, audits) | C36: 265000 | F36: ₹/month | G36: Assumption
A37: mkt_m | B37: Brand content and PR per month (on top of per-unit acquisition) | C37: 75000 | F37: ₹/month | G37: Assumption
A38: capex | B38: Launch spend in month 1 (samples, shoot, website, certification set-up) | C38: 800000 | F38: ₹ | G38: Assumption
A39: units_y1 | B39: Units, year 1 (Jul 2027–Jun 2028) | C39: 1800 | F39: sets | G39: Sizing v1: 24-month SOM ≈ 4,200 sets at 0.5% of SAM (Sizing!B27)
A40: units_y2 | B40: Units, year 2 (Jul 2028–Jun 2029) | C40: 3000 | F40: sets | G40: Sizing v1 (growth as channels add)
A41: mp_lag | B41: Marketplace settlement delay | C41: 1 | F41: months | G41: Register / practitioner norm; assumption
A42: lead | B42: Production lead time (stock paid a month before sale) | C42: 1 | F42: months | G42: Assumption; Trends peak Oct–Nov means stock lands by Sep
A44: SEASONALITY
A45: Month | B45: kurta for men index | C45: wedding outfit index | D45: Blend | E45: Weight | G45: Source: Google Trends India, 2022–2025 average, each year's mean = 100 (data/clean/desk_results.json)
...

Sheet Range_Cost
A1: Range, price and cost stack per set
A2: All formulas. Green = link to Assumptions.
A4: Line | B4: Price (₹) | C4: GST rate | D4: Net price ex-GST (₹) | E4: Fabric (₹) | F4: Wastage (₹) | G4: CMT (₹) | H4: Trims (₹) | I4: Packaging (₹) | J4: Certification (₹) | K4: COGS (₹) | L4: Gross margin (₹) | M4: Gross margin % | N4: Clears 50% floor (H4)? | O4: Units share
A5: Everyday | B5: =Assumptions!$C$5 -> 2499 | C5: =IF(B5<=Assumptions!$C$18,Assumptions!$C$16,Assumptions!$C$17) -> 0.05 | D5: =B5/(1+C5) -> 2380 | E5: =Assumptions!$C$6*Assumptions!$C$7 -> 900 | F5: =(E5+H5)*Assumptions!$C$12 -> 76.8 | G5: =Assumptions!$C$8 -> 350 | H5: =Assumptions!$C$9 -> 60 | I5: =Assumptions!$C$10 -> 90 | J5: =Assumptions!$C$11 -> 30 | K5: =SUM(E5:J5) -> 1506.8 | L5: =D5-K5 -> 873.2 | M5: =IF(D5=0,0,L5/D5) -> 0.36689076 | N5: =IF(M5>=0.5,"yes","NO") -> NO | O5: =Assumptions!$C$13 -> 0.45
A6: Festive | B6: =Assumptions!$D$5 -> 4999 | C6: =IF(B6<=Assumptions!$C$18,Assumptions!$C$16,Assumptions!$C$17) -> 0.18 | D6: =B6/(1+C6) -> 4236.4407 | E6: =Assumptions!$D$6*Assumptions!$D$7 -> 1750 | F6: =(E6+H6)*Assumptions!$D$12 -> 149.6 | G6: =Assumptions!$D$8 -> 500 | H6: =Assumptions!$D$9 -> 120 | I6: =Assumptions!$D$10 -> 150 | J6: =Assumptions!$D$11 -> 30 | K6: =SUM(E6:J6) -> 2699.6 | L6: =D6-K6 -> 1536.8407 | M6: =IF(D6=0,0,L6/D6) -> 0.36276695 | N6: =IF(M6>=0.5,"yes","NO") -> NO | O6: =Assumptions!$D$13 -> 0.4
A7: Ceremonial | B7: =Assumptions!$E$5 -> 8999 | C7: =IF(B7<=Assumptions!$C$18,Assumptions!$C$16,Assumptions!$C$17) -> 0.18 | D7: =B7/(1+C7) -> 7626.2712 | E7: =Assumptions!$E$6*Assumptions!$E$7 -> 3375 | F7: =(E7+H7)*Assumptions!$E$12 -> 362.5 | G7: =Assumptions!$E$8 -> 1200 | H7: =Assumptions!$E$9 -> 250 | I7: =Assumptions!$E$10 -> 300 | J7: =Assumptions!$E$11 -> 40 | K7: =SUM(E7:J7) -> 5527.5 | L7: =D7-K7 -> 2098.7712 | M7: =IF(D7=0,0,L7/D7) -> 0.2752028 | N7: =IF(M7>=0.5,"yes","NO") -> NO | O7: =Assumptions!$E$13 -> 0.15
A8: Weighted | D8: =SUMPRODUCT(D5:D7,$O$5:$O$7) -> 3909.5169 | K8: =SUMPRODUCT(K5:K7,$O$5:$O$7) -> 2587.025 | L8: =SUMPRODUCT(L5:L7,$O$5:$O$7) -> 1322.4919 | M8: =IF(D8=0,0,L8/D8) -> 0.33827503
A10: Reading: the everyday line is held under the ₹2,500 GST slab and priced below Manyavar's ₹2,624 natural-fibre set, so it cannot reach a 50% gross margin with certified fabric. It works as an entry and traffic line; margin comes from festive and ceremonial.

Sheet Channel_Waterfalls
A1: Contribution per set, by line and channel
A2: One column per line × channel. Contribution = net revenue − COGS − channel costs − acquisition.
A4: ₹ per set sold | B4: Everyday D2C website | C4: Everyday Marketplace | D4: Everyday Pop-up | E4: Everyday Corporate gifting | F4: Festive D2C website | G4: Festive Marketplace | H4: Festive Pop-up | I4: Festive Corporate gifting | J4: Ceremonial D2C website | K4: Ceremonial Marketplace | L4: Ceremonial Pop-up | M4: Ceremonial Corporate gifting
A5: Net price ex-GST | B5: =Range_Cost!$D$5 -> 2380 | C5: =Range_Cost!$D$5 -> 2380 | D5: =Range_Cost!$D$5 -> 2380 | E5: =Range_Cost!$D$5 -> 2380 | F5: =Range_Cost!$D$6 -> 4236.4407 | G5: =Range_Cost!$D$6 -> 4236.4407 | H5: =Range_Cost!$D$6 -> 4236.4407 | I5: =Range_Cost!$D$6 -> 4236.4407 | J5: =Range_Cost!$D$7 -> 7626.2712 | K5: =Range_Cost!$D$7 -> 7626.2712 | L5: =Range_Cost!$D$7 -> 7626.2712 | M5: =Range_Cost!$D$7 -> 7626.2712
A6: Customer / buyer discount | B6: =-B5*Assumptions!$C$23 -> 0 | C6: =-C5*Assumptions!$D$23 -> 0 | D6: =-D5*Assumptions!$E$23 -> 0 | E6: =-E5*Assumptions!$F$23 -> -357 | F6: =-F5*Assumptions!$C$23 -> 0 | G6: =-G5*Assumptions!$D$23 -> 0 | H6: =-H5*Assumptions!$E$23 -> 0 | I6: =-I5*Assumptions!$F$23 -> -635.4661 | J6: =-J5*Assumptions!$C$23 -> 0 | K6: =-K5*Assumptions!$D$23 -> 0 | L6: =-L5*Assumptions!$E$23 -> 0 | M6: =-M5*Assumptions!$F$23 -> -1143.9407
A7: Net revenue | B7: =B5+B6 -> 2380 | C7: =C5+C6 -> 2380 | D7: =D5+D6 -> 2380 | E7: =E5+E6 -> 2023 | F7: =F5+F6 -> 4236.4407 | G7: =G5+G6 -> 4236.4407 | H7: =H5+H6 -> 4236.4407 | I7: =I5+I6 -> 3600.9746 | ... M7: =M5+M6 -> 6482.3305
A8: COGS | B8: =-Range_Cost!$K$5 -> -1506.8 | C8: =-Range_Cost!$K$5 -> -1506.8 | D8: =-Range_Cost!$K$5 -> -1506.8 | E8: =-Range_Cost!$K$5 -> -1506.8 | F8: =-Range_Cost!$K$6 -> -2699.6 | G8: =-Range_Cost!$K$6 -> -2699.6 | H8: =-Range_Cost!$K$6 -> -2699.6 | I8: =-Range_Cost!$K$6 -> -2699.6 | J8: =-Range_Cost!$K$7 -> -5527.5 | K8: =-Range_Cost!$K$7 -> -5527.5 | L8: =-Range_Cost!$K$7 -> -5527.5 | M8: =-Range_Cost!$K$7 -> -5527.5
A9: Gross margin | B9: =B7+B8 -> 873.2 | C9: =C7+C8 -> 873.2 | D9: =D7+D8 -> 873.2 | E9: =E7+E8 -> 516.2 | F9: =F7+F8 -> 1536.8407 | G9: =G7+G8 -> 1536.8407 | H9: =H7+H8 -> 1536.8407 | I9: =I7+I8 -> 901.37458 | ... M9: =M7+M8 -> 954.83051
A10: Commission | B10: =-B7*Assumptions!$C$24 -> 0 | C10: =-C7*Assumptions!$D$24 -> -654.5 | D10: =-D7*Assumptions!$E$24 -> 0 | E10: =-E7*Assumptions!$F$24 -> 0 | F10: =-F7*Assumptions!$C$24 -> 0 | G10: =-G7*Assumptions!$D$24 -> -1165.0212 | H10: =-H7*Assumptions!$E$24 -> 0 | I10: =-I7*Assumptions!$F$24 -> 0 | J10: =-J7*Assumptions!$C$24 -> 0 | K10: =-K7*Assumptions!$D$24 -> -2097.2246 | L10: =-L7*Assumptions!$E$24 -> 0 | M10: =-M7*Assumptions!$F$24 -> 0
A11: Fixed fee | B11: =-Assumptions!$C$25 -> 0 | C11: =-Assumptions!$D$25 -> -25 | D11: =-Assumptions!$E$25 -> 0 | E11: =-Assumptions!$F$25 -> 0 | F11: =-Assumptions!$C$25 -> 0 | G11: =-Assumptions!$D$25 -> -25 | H11: =-Assumptions!$E$25 -> 0 | I11: =-Assumptions!$F$25 -> 0 | J11: =-Assumptions!$C$25 -> 0 | K11: =-Assumptions!$D$25 -> -25 | L11: =-Assumptions!$E$25 -> 0 | M11: =-Assumptions!$F$25 -> 0
A12: Payment gateway | B12: =-B7*Assumptions!$C$26 -> -56.168 | C12: =-C7*Assumptions!$D$26 -> 0 | D12: =-D7*Assumptions!$E$26 -> -56.168 | E12: =-E7*Assumptions!$F$26 -> 0 | F12: =-F7*Assumptions!$C$26 -> -99.98 | G12: =-G7*Assumptions!$D$26 -> 0 | H12: =-H7*Assumptions!$E$26 -> -99.98 | I12: =-I7*Assumptions!$F$26 -> 0 | J12: =-J7*Assumptions!$C$26 -> -179.98 | K12: =-K7*Assumptions!$D$26 -> 0 | L12: =-L7*Assumptions!$E$26 -> -179.98 | M12: =-M7*Assumptions!$F$26 -> 0
A13: Forward shipping | B13: =-Assumptions!$C$27 -> -60 | C13: =-Assumptions!$D$27 -> -90 | D13: =-Assumptions!$E$27 -> 0 | E13: =-Assumptions!$F$27 -> -30 | F13: =-Assumptions!$C$27 -> -60 | G13: =-Assumptions!$D$27 -> -90 | H13: =-Assumptions!$E$27 -> 0 | I13: =-Assumptions!$F$27 -> -30 | J13: =-Assumptions!$C$27 -> -60 | K13: =-Assumptions!$D$27 -> -90 | L13: =-Assumptions!$E$27 -> 0 | M13: =-Assumptions!$F$27 -> -30
A14: Returns cost | B14: =-Assumptions!$C$28*(Assumptions!$C$27+Assumptions!$C$29+B7*Assumptions!$C$30) -> -73.6 | C14: =-Assumptions!$D$28*(Assumptions!$D$27+Assumptions!$D$29+C7*Assumptions!$D$30) -> -104.5 | D14: =-Assumptions!$E$28*(Assumptions!$E$27+Assumptions!$E$29+D7*Assumptions!$E$30) -> -7.14 | E14: =-Assumptions!$F$28*(Assumptions!$F$27+Assumptions!$F$29+E7*Assumptions!$F$30) -> -4.646 | F14: =-Assumptions!$C$28*(Assumptions!$C$27+Assumptions!$C$29+F7*Assumptions!$C$30) -> -110.72881 | G14: =-Assumptions!$D$28*(Assumptions!$D$27+Assumptions!$D$29+G7*Assumptions!$D$30) -> -150.91102 | H14: =-Assumptions!$E$28*(Assumptions!$E$27+Assumptions!$E$29+H7*Assumptions!$E$30) -> -12.709322 | I14: =-Assumptions!$F$28*(Assumptions!$F$27+Assumptions!$F$29+I7*Assumptions!$F$30) -> -7.8019492 | J14: =-Assumptions!$C$28*(Assumptions!$C$27+Assumptions!$C$29+J7*Assumptions!$C$30) -> -178.52542 | K14: =-Assumptions!$D$28*(Assumptions!$D$27+Assumptions!$D$29+K7*Assumptions!$D$30) -> -235.65678 | L14: =-Assumptions!$E$28*(Assumptions!$E$27+Assumptions!$E$29+L7*Assumptions!$E$30) -> -22.878814 | M14: =-Assumptions!$F$28*(Assumptions!$F$27+Assumptions!$F$29+M7*Assumptions!$F$30) -> -13.564661
A15: COD return-to-origin cost | B15: =-Assumptions!$C$31*Assumptions!$C$32*(Assumptions!$C$27+Assumptions!$C$29) -> -16.64 | C15: =-Assumptions!$D$31*Assumptions!$D$32*(Assumptions!$D$27+Assumptions!$D$29) -> 0 | D15: =-Assumptions!$E$31*Assumptions!$E$32*(Assumptions!$E$27+Assumptions!$E$29) -> 0 | E15: =-Assumptions!$F$31*Assumptions!$F$32*(Assumptions!$F$27+Assumptions!$F$29) -> 0 | F15: =-Assumptions!$C$31*Assumptions!$C$32*(Assumptions!$C$27+Assumptions!$C$29) -> -16.64 | G15: =-Assumptions!$D$31*Assumptions!$D$32*(Assumptions!$D$27+Assumptions!$D$29) -> 0 | H15: =-Assumptions!$E$31*Assumptions!$E$32*(Assumptions!$E$27+Assumptions!$E$29) -> 0 | I15: =-Assumptions!$F$31*Assumptions!$F$32*(Assumptions!$F$27+Assumptions!$F$29) -> 0 | J15: =-Assumptions!$C$31*Assumptions!$C$32*(Assumptions!$C$27+Assumptions!$C$29) -> -16.64 | K15: =-Assumptions!$D$31*Assumptions!$D$32*(Assumptions!$D$27+Assumptions!$D$29) -> 0 | L15: =-Assumptions!$E$31*Assumptions!$E$32*(Assumptions!$E$27+Assumptions!$E$29) -> 0 | M15: =-Assumptions!$F$31*Assumptions!$F$32*(Assumptions!$F$27+Assumptions!$F$29) -> 0
A16: Acquisition / venue | B16: =-Assumptions!$C$33*Scenarios!$C$8 -> -550 | C16: =-Assumptions!$D$33*Scenarios!$C$8 -> -150 | D16: =-Assumptions!$E$33*Scenarios!$C$8 -> -450 | E16: =-Assumptions!$F$33*Scenarios!$C$8 -> -200 | F16: =-Assumptions!$C$33*Scenarios!$C$8 -> -550 | G16: =-Assumptions!$D$33*Scenarios!$C$8 -> -150 | H16: =-Assumptions!$E$33*Scenarios!$C$8 -> -450 | I16: =-Assumptions!$F$33*Scenarios!$C$8 -> -200 | J16: =-Assumptions!$C$33*Scenarios!$C$8 -> -550 | K16: =-Assumptions!$D$33*Scenarios!$C$8 -> -150 | L16: =-Assumptions!$E$33*Scenarios!$C$8 -> -450 | M16: =-Assumptions!$F$33*Scenarios!$C$8 -> -200
A17: Contribution | B17: =SUM(B9:B16) -> 116.792 | C17: =SUM(C9:C16) -> -150.8 | D17: =SUM(D9:D16) -> 359.892 | E17: =SUM(E9:E16) -> 281.554 | F17: =SUM(F9:F16) -> 699.49186 | G17: =SUM(G9:G16) -> -44.091525 | H17: =SUM(H9:H16) -> 974.15136 | I17: =SUM(I9:I16) -> 663.57263 | ... M17: =SUM(M9:M16) -> 711.26585
A18: Contribution % | B18: =IF(B7=0,0,B17/B7) -> 0.049072269 | C18: =IF(C7=0,0,C17/C7) -> -0.063361345 | D18: =IF(D7=0,0,D17/D7) -> 0.15121513 | E18: =IF(E7=0,0,E17/E7) -> 0.13917647 | F18: =IF(F7=0,0,F17/F7) -> 0.1651131 | G18: =IF(G7=0,0,G17/G7) -> -0.010407682 | H18: =IF(H7=0,0,H17/H7) -> 0.22994571 | I18: =IF(I7=0,0,I17/I7) -> 0.18427584 | ... M18: =IF(M7=0,0,M17/M7) -> 0.10972379
A19: Unit mix weight | B19: =Range_Cost!$O$5*Assumptions!$C$22 -> 0.1575 | C19: =Range_Cost!$O$5*Assumptions!$D$22 -> 0.135 | D19: =Range_Cost!$O$5*Assumptions!$E$22 -> 0.09 | E19: =Range_Cost!$O$5*Assumptions!$F$22 -> 0.0675 | F19: =Range_Cost!$O$6*Assumptions!$C$22 -> 0.14 | G19: =Range_Cost!$O$6*Assumptions!$D$22 -> 0.12 | H19: =Range_Cost!$O$6*Assumptions!$E$22 -> 0.08 | I19: =Range_Cost!$O$6*Assumptions!$F$22 -> 0.06 | J19: =Range_Cost!$O$7*Assumptions!$C$22 -> 0.0525 | K19: =Range_Cost!$O$7*Assumptions!$D$22 -> 0.045 | L19: =Range_Cost!$O$7*Assumptions!$E$22 -> 0.03 | M19: =Range_Cost!$O$7*Assumptions!$F$22 -> 0.0225
A21: Blended per set (mix-weighted)
A22: Net revenue | B22: =SUMPRODUCT(B7:M7,B19:M19) -> 3821.5528
A23: COGS | B23: =SUMPRODUCT(B8:M8,B19:M19) -> -2587.025
A24: Channel + acquisition costs | B24: =SUMPRODUCT(B10:M10,B19:M19)+SUMPRODUCT(B11:M11,B19:M19)+SUMPRODUCT(B12:M12,B19:M19)+SUMPRODUCT(B13:M13,B19:M19)+SUMPRODUCT(B14:M14,B19:M19)+SUMPRODUCT(B15:M15,B19:M19)+SUMPRODUCT(B16:M16,B19:M19) -> -879.32531
A25: Contribution per set | B25: =B22+B23+B24 -> 355.20251
A26: Blended contribution % | B26: =IF(B22=0,0,B25/B22) -> 0.092947167

Sheet Demand_Cash_24M
A1: 24-month demand, P&L and cash (Jul 2027 – Jun 2029)
A2: Units follow the Google Trends season; stock is paid one month before it sells; marketplace cash lands one month late.
Z3: Month 25 shown only to time the last stock purchase
A4: Month | B4: 46569 | C4: 46600 | D4: 46631 | E4: 46661 | F4: 46692 | G4: 46722 | H4: 46753 | I4: 46784 | J4: 46813 | K4: 46844 | L4: 46874 | M4: 46905 | N4: 46935 | O4: 46966 | P4: 46997 | Q4: 47027 | R4: 47058 | S4: 47088 | T4: 47119 | U4: 47150 | V4: 47178 | W4: 47209 | X4: 47239 | Y4: 47270 | Z4: 47300
A5: Calendar month no. | B5: 7 | C5: 8 | D5: 9 | E5: 10 | F5: 11 | G5: 12 | H5: 1 | I5: 2 | J5: 3 | K5: 4 | L5: 5 | M5: 6 | N5: 7 | O5: 8 | P5: 9 | Q5: 10 | R5: 11 | S5: 12 | T5: 1 | U5: 2 | V5: 3 | W5: 4 | X5: 5 | Y5: 6 | Z5: 7
A6: Year of plan | B6: 1 | C6: 1 | D6: 1 | E6: 1 | F6: 1 | G6: 1 | H6: 1 | I6: 1 | J6: 1 | K6: 1 | L6: 1 | M6: 1 | N6: 2 | O6: 2 | P6: 2 | Q6: 2 | R6: 2 | S6: 2 | T6: 2 | U6: 2 | V6: 2 | W6: 2 | X6: 2 | Y6: 2 | Z6: 2
A7: Season weight | B7: =INDEX(Assumptions!$E$46:$E$57,B5) -> 0.039150354 | C7: =INDEX(Assumptions!$E$46:$E$57,C5) -> 0.054144107 | D7: =INDEX(Assumptions!$E$46:$E$57,D5) -> 0.070803832 | E7: =INDEX(Assumptions!$E$46:$E$57,E5) -> 0.1211995 | F7: =INDEX(Assumptions!$E$46:$E$57,F5) -> 0.13494377 | G7: =INDEX(Assumptions!$E$46:$E$57,G5) -> 0.085381091 | H7: =INDEX(Assumptions!$E$46:$E$57,H5) -> 0.088713036 | I7: =INDEX(Assumptions!$E$46:$E$57,I5) -> 0.093294461 | ... Z7: =INDEX(Assumptions!$E$46:$E$57,Z5) -> 0.039150354
A8: Units sold | B8: =IF(B6=1,Assumptions!$C$39,Assumptions!$C$40)*B7*Scenarios!$C$6 -> 70.470637 | C8: =IF(C6=1,Assumptions!$C$39,Assumptions!$C$40)*C7*Scenarios!$C$6 -> 97.459392 | D8: =IF(D6=1,Assumptions!$C$39,Assumptions!$C$40)*D7*Scenarios!$C$6 -> 127.4469 | E8: =IF(E6=1,Assumptions!$C$39,Assumptions!$C$40)*E7*Scenarios!$C$6 -> 218.1591 | F8: =IF(F6=1,Assumptions!$C$39,Assumptions!$C$40)*F7*Scenarios!$C$6 -> 242.89879 | G8: =IF(G6=1,Assumptions!$C$39,Assumptions!$C$40)*G7*Scenarios!$C$6 -> 153.68596 | H8: =IF(H6=1,Assumptions!$C$39,Assumptions!$C$40)*H7*Scenarios!$C$6 -> 159.68347 | I8: =IF(I6=1,Assumptions!$C$39,Assumptions!$C$40)*I7*Scenarios!$C$6 -> 167.93003 | ... Z8: =IF(Z6=1,Assumptions!$C$39,Assumptions!$C$40)*Z7*Scenarios!$C$6 -> 117.45106
A9: Revenue ex-GST | B9: =B8*Channel_Waterfalls!$B$22*Scenarios!$C$7 -> 269307.26 | C9: =C8*Channel_Waterfalls!$B$22*Scenarios!$C$7 -> 372446.21 | D9: =D8*Channel_Waterfalls!$B$22*Scenarios!$C$7 -> 487045.05 | E9: =E8*Channel_Waterfalls!$B$22*Scenarios!$C$7 -> 833706.52 | F9: =F8*Channel_Waterfalls!$B$22*Scenarios!$C$7 -> 928250.56 | G9: =G8*Channel_Waterfalls!$B$22*Scenarios!$C$7 -> 587319.03 | H9: =H8*Channel_Waterfalls!$B$22*Scenarios!$C$7 -> 610238.8 | I9: =I8*Channel_Waterfalls!$B$22*Scenarios!$C$7 -> 641753.48 | ... Z9: =Z8*Channel_Waterfalls!$B$22*Scenarios!$C$7 -> 448845.44
A10: COGS | B10: =B8*Channel_Waterfalls!$B$23 -> -182309.3 | C10: =C8*Channel_Waterfalls!$B$23 -> -252129.88 | D10: =D8*Channel_Waterfalls!$B$23 -> -329708.31 | E10: =E8*Channel_Waterfalls!$B$23 -> -564383.05 | F10: =F8*Channel_Waterfalls!$B$23 -> -628385.25 | G10: =G8*Channel_Waterfalls!$B$23 -> -397589.43 | H10: =H8*Channel_Waterfalls!$B$23 -> -413105.12 | I10: =I8*Channel_Waterfalls!$B$23 -> -434439.18 | ... Z10: =Z8*Channel_Waterfalls!$B$23 -> -303848.83
A11: Channel + acquisition costs | B11: =B8*Channel_Waterfalls!$B$24 -> -61966.615 | C11: =C8*Channel_Waterfalls!$B$24 -> -85698.51 | D11: =D8*Channel_Waterfalls!$B$24 -> -112067.28 | E11: =E8*Channel_Waterfalls!$B$24 -> -191832.82 | F11: =F8*Channel_Waterfalls!$B$24 -> -213587.06 | G11: =G8*Channel_Waterfalls!$B$24 -> -135139.96 | H11: =H8*Channel_Waterfalls!$B$24 -> -140413.71 | I11: =I8*Channel_Waterfalls!$B$24 -> -147665.13 | ... Z11: =Z8*Channel_Waterfalls!$B$24 -> -103277.69
A12: Contribution | B12: =B9+B10+B11 -> 25031.347 | C12: =C9+C10+C11 -> 34617.82 | D12: =D9+D10+D11 -> 45269.457 | E12: =E9+E10+E11 -> 77490.659 | F12: =F9+F10+F11 -> 86278.26 | G12: =G9+G10+G11 -> 54589.64 | H12: =H9+H10+H11 -> 56719.967 | I12: =I9+I10+I11 -> 59649.167 | ... Z12: =Z9+Z10+Z11 -> 41718.912
A13: Fixed overheads | B13: =-Assumptions!$C$36*Scenarios!$C$9 -> -265000 | C13: =-Assumptions!$C$36*Scenarios!$C$9 -> -265000 | D13: =-Assumptions!$C$36*Scenarios!$C$9 -> -265000 | E13: =-Assumptions!$C$36*Scenarios!$C$9 -> -265000 | F13: =-Assumptions!$C$36*Scenarios!$C$9 -> -265000 | G13: =-Assumptions!$C$36*Scenarios!$C$9 -> -265000 | H13: =-Assumptions!$C$36*Scenarios!$C$9 -> -265000 | I13: =-Assumptions!$C$36*Scenarios!$C$9 -> -265000 | ... Z13: =-Assumptions!$C$36*Scenarios!$C$9 -> -265000
A14: Brand content | B14: =-Assumptions!$C$37 -> -75000 | C14: =-Assumptions!$C$37 -> -75000 | D14: =-Assumptions!$C$37 -> -75000 | E14: =-Assumptions!$C$37 -> -75000 | F14: =-Assumptions!$C$37 -> -75000 | G14: =-Assumptions!$C$37 -> -75000 | H14: =-Assumptions!$C$37 -> -75000 | I14: =-Assumptions!$C$37 -> -75000 | ... Z14: =-Assumptions!$C$37 -> -75000
A15: Launch spend | B15: =-Assumptions!$C$38 -> -800000 | C15: 0 | D15: 0 | E15: 0 | F15: 0 | G15: 0 | H15: 0 | I15: 0 | J15: 0 | K15: 0 | L15: 0 | M15: 0 | N15: 0 | O15: 0 | P15: 0 | Q15: 0 | R15: 0 | S15: 0 | T15: 0 | U15: 0 | V15: 0 | W15: 0 | X15: 0 | Y15: 0 | Z15: 0
A16: EBITDA | B16: =SUM(B12:B15) -> -1114968.7 | C16: =SUM(C12:C15) -> -305382.18 | D16: =SUM(D12:D15) -> -294730.54 | E16: =SUM(E12:E15) -> -262509.34 | F16: =SUM(F12:F15) -> -253721.74 | G16: =SUM(G12:G15) -> -285410.36 | H16: =SUM(H12:H15) -> -283280.03 | I16: =SUM(I12:I15) -> -280350.83 | ... Z16: =SUM(Z12:Z15) -> -298281.09
A17: Cumulative EBITDA | B17: =B16 -> -1114968.7 | C17: =B17+C16 -> -1420350.8 | D17: =C17+D16 -> -1715081.4 | E17: =D17+E16 -> -1977590.7 | F17: =E17+F16 -> -2231312.5 | G17: =F17+G16 -> -2516722.8 | H17: =G17+H16 -> -2800002.8 | I17: =H17+I16 -> -3080353.7 | J17: =I17+J16 -> -3362036 | ... Z17: =Y17+Z16 -> -7553309.1
A18: Stock purchase (next month's COGS) | B18: =C10 -> -252129.88 | C18: =D10 -> -329708.31 | D18: =E10 -> -564383.05 | E18: =F10 -> -628385.25 | F18: =G10 -> -397589.43 | G18: =H10 -> -413105.12 | H18: =I10 -> -434439.18 | I18: =J10 -> -424741.88 | ... X18: =Y10 -> -349102.92 | Y18: =Y10 -> -349102.92 | Z18: =Z10 -> -303848.83
A19: Marketplace receivable change | B19: =-B9*(Assumptions!$D$22) -> -80792.179 | C19: =-(C9-B9)*(Assumptions!$D$22) -> -30941.685 | D19: =-(D9-C9)*(Assumptions!$D$22) -> -34379.651 | E19: =-(E9-D9)*(Assumptions!$D$22) -> -103998.44 | F19: =-(F9-E9)*(Assumptions!$D$22) -> -28363.212 | G19: =-(G9-F9)*(Assumptions!$D$22) -> 102279.46 | H19: =-(H9-G9)*(Assumptions!$D$22) -> -6875.9301 | I19: =-(I9-H9)*(Assumptions!$D$22) -> -9454.4039 | J19: =-(J9-I9)*(Assumptions!$D$22) -> 4297.4563 | ... Z19: =-(Z9-Y9)*(Assumptions!$D$22) -> 20054.796
A20: Cash flow | B20: =B16+B18+B19 -> -1447890.7 | C20: =C16-C10+C18+C19 -> -413902.29 | D20: =D16-D10+D18+D19 -> -563784.93 | E20: =E16-E10+E18+E19 -> -430509.98 | F20: =F16-F10+F18+F19 -> -51289.135 | G20: =G16-G10+G18+G19 -> -198646.59 | H20: =H16-H10+H18+H19 -> -311490.03 | I20: =I16-I10+I18+I19 -> -280107.93 | J20: =J16-J10+J18+J19 -> -374357.86 | ... Z20: =Z16-Z10+Z18+Z19 -> -278226.29
A21: Cumulative cash | B21: =B20 -> -1447890.7 | C21: =B21+C20 -> -1861793 | D21: =C21+D20 -> -2425577.9 | E21: =D21+E20 -> -2856087.9 | F21: =E21+F20 -> -2907377.1 | G21: =F21+G20 -> -3106023.6 | H21: =G21+H20 -> -3417513.7 | I21: =H21+I20 -> -3697621.6 | J21: =I21+J20 -> -4071979.5 | ... Z21: =Y21+Z20 -> -8037065.6

Sheet Sizing
A1: Market sizing v1: top-down vs bottom-up (₹ crore unless stated)
A3: TOP-DOWN
A4: Men's ethnic wear (US$ bn) | B4: =Inputs!$B$2 -> 3.1
A5: × ₹ per US$ → ₹ crore | B5: =B4*Inputs!$B$3*1000000000/10000000 -> 26660
A6: × organised share | B6: =B5*Inputs!$B$4 -> 4665.5
A7: × premium share of organised | B7: =B6*Inputs!$B$5 -> 1399.65
A8: × four-metro share = top-down SAM (₹ crore) | B8: =B7*Inputs!$B$6 -> 419.895
A10: BOTTOM-UP (SAM = H × m × f × ASP)
B11: Mumbai | C11: Delhi NCR | D11: Bengaluru | E11: Pune | F11: Total
A12: Population 2011 (UA) | B12: =Inputs!$B$7 -> 18394912 | C12: =Inputs!$B$8 -> 16349831 | D12: =Inputs!$B$9 -> 8520435 | E12: =Inputs!$B$10 -> 5057709 | F12: =SUM(B12:E12) -> 48322887
A13: Population 2026 (× growth; Delhi × NCR uplift) | B13: =B12*Inputs!$B$11 -> 24833131 | C13: =C12*Inputs!$B$11*Inputs!$B$12 -> 29797567 | D13: =D12*Inputs!$B$11 -> 11502587 | E13: =E12*Inputs!$B$11 -> 6827907.2 | F13: =SUM(B13:E13) -> 72961193
A14: Households (÷ household size) | B14: =B13/Inputs!$B$13 -> 5912650.3 | C14: =C13/Inputs!$B$13 -> 7094658.8 | D14: =D13/Inputs!$B$13 -> 2738711.2 | E14: =E13/Inputs!$B$13 -> 1625692.2 | F14: =SUM(B14:E14) -> 17371713
A15: H: households with income > ₹30 lakh | B15: =B14*Inputs!$B$14 -> 709518.03 | C15: =C14*Inputs!$B$14 -> 851359.06 | D15: =D14*Inputs!$B$14 -> 328645.35 | E15: =E14*Inputs!$B$14 -> 195083.06 | F15: =SUM(B15:E15) -> 2084605.5
A16: × m: men aged 40–60 | B16: =B15*Inputs!$B$15 -> 283807.21 | C16: =C15*Inputs!$B$15 -> 340543.62 | D16: =D15*Inputs!$B$15 -> 131458.14 | E16: =E15*Inputs!$B$15 -> 78033.225 | F16: =SUM(B16:E16) -> 833842.2
A17: × f: sets per year | B17: =B16*Inputs!$B$16 -> 425710.82 | C17: =C16*Inputs!$B$16 -> 510815.43 | D17: =D16*Inputs!$B$16 -> 197187.21 | E17: =E16*Inputs!$B$16 -> 117049.84 | F17: =SUM(B17:E17) -> 1250763.3
A18: × ASP: SAM (₹ crore) | B18: =B17*Inputs!$B$17/10000000 -> 212.85541 | C18: =C17*Inputs!$B$17/10000000 -> 255.40772 | D18: =D17*Inputs!$B$17/10000000 -> 98.593605 | E18: =E17*Inputs!$B$17/10000000 -> 58.524918 | F18: =SUM(B18:E18) -> 625.38165
A20: COMPARISON
A21: Top-down SAM (₹ crore) | B21: =B8 -> 419.895
A22: Bottom-up SAM (₹ crore) | B22: =F18 -> 625.38165
A23: Ratio: bottom-up ÷ top-down | B23: =IF(B21=0,"",B22/B21) -> 1.4893763
A24: Within 2× of each other? (H3 test) | B24: =IF(B23="","",IF(AND(B23>=0.5,B23<=2),"yes","NO")) -> yes
A25: SAM used for SOM (lower of the two, ₹ crore) | B25: =MIN(B21,B22) -> 419.895
A26: SOM: 24-month reachable revenue (₹ crore) | B26: =B25*Inputs!$B$18 -> 2.099475
A27: SOM in sets (÷ ASP) | B27: =B26*10000000/Inputs!$B$17 -> 4198.95
A29: WHY THE TWO VIEWS DIFFER
A30: • Bottom-up counts every set that men aged 40–60 in high-income households buy, at a premium ASP, including sets now bought from tailors, unbranded shops and luxury labels. Top-down counts only the organised premium tier, for all ages.
A31: • Top-down excludes the luxury tier (30% of organised) and all unorganised spend, so it is conservative for a premium brand.
A32: • The bottom-up figure is most sensitive to the rich-household share (Inputs row 14), which has no city-level source. Treat it as the input to test in Scenarios_Sensitivity.
A33: • SOM here is a placeholder share; D8's channel and budget plan replaces it with a bottom-up estimate of reachable customers.
